Workbook

Sheet BASE_ARTICLE
A1: ID_ARTICLES | B1: DESIGNATION | C1: NATURE | D1: CATEGORIE | E1: IMPUT1 | F1: IMPUT2 | G1: IMPUT3 | H1: IMPUT4 | I1: IMPUT5 | J1: IMPUT6 | K1: IMPUT7 | L1: IMPUT8 | M1: IMPUT9 | N1: IMPUT10 | O1: IMPUT11 | P1: IMPUT12 | Q1: IMPUT13 | R1: IMPUT14 | S1: IMPUT15 | T1: IMPUT16 | U1: IMPUT17 | V1: IMPUT18 | W1: IMPUT19 | X1: IMPUT20 | Y1: IMPUT21 | Z1: IMPUT22 | AA1: IMPUT23 | AB1: IMPUT24 | AC1: IMPUT25 | AD1: IMPUT26 | AE1: IMPUT27 | AF1: IMPUT28 | AG1: IMPUT29 | AH1: IMPUT30 | AI1: IMPUT31 | AJ1: IMPUT32 | AK1: IMPUT33 | AL1: IMPUT34 | AM1: IMPUT35 | AN1: IMPUT36 | AO1: IMPUT37 | AP1: IMPUT38 | AQ1: IMPUT39 | AR1: IMPUT40 | AS1: IMPUT41 | AT1: IMPUT42 | AU1: IMPUT43 | AV1: IMPUT44 | AW1: IMPUT45 | AX1: IMPUT46 | AY1: IMPUT47 | AZ1: IMPUT48 | BA1: IMPUT49 | BB1: IMPUT50 | BC1: MACH1 | BD1: MACH2 | BE1: MACH3 | BF1: MACH4 | BG1: MACH5 | BH1: MACH6 | BI1: MACH7 | BJ1: MACH8 | BK1: MACH9 | BL1: MACH10 | BM1: MACH11 | BN1: MACH12 | BO1: MACH13 | BP1: MACH14 | BQ1: MACH15 | BR1: MACH16 | BS1: MACH17 | BT1: MACH18 | BU1: MACH19 | BV1: MACH20
A2: ART-0001 | B2: Carte de visite | C2: 85×55 recto couché mat 300 g | D2: Impression numérique petit format | H2: 0.0125 | AQ2: 0.006 | BC2: 0.05 | BM2: 0.04
A3: ART-0002 | B3: Carte de visite | C3: 85×55 recto couché mat 300 g pelliculage mat | D3: Impression numérique petit format | H3: 0.0125 | AK3: 0.0225 | AQ3: 0.006 | BC3: 0.05 | BM3: 0.04 | BQ3: 0.14
A4: ART-0003 | B4: Carte de visite | C4: 85×55 recto couché mat 300 g pelliculage brillant | D4: Impression numérique petit format | H4: 0.0125 | AL4: 0.0225 | AQ4: 0.006 | BC4: 0.05 | BM4: 0.04 | BQ4: 0.14
A5: ART-0004 | B5: Carte de visite | C5: 85×55 recto couché mat 300 g pelliculage mat + vernis sélectif | D5: Impression numérique petit format | H5: 0.0125 | AK5: 0.0225 | AQ5: 0.006 | BA5: 0.03 | BC5: 0.05 | BM5: 0.04 | BQ5: 0.14 | BS5: 0.15
A6: ART-0005 | B6: Carte de visite | C6: 85×55 recto-verso couché mat 300 g | D6: Impression numérique petit format | H6: 0.0125 | AQ6: 0.012 | BC6: 0.1 | BM6: 0.04
A7: ART-0006 | B7: Carte de visite | C7: 85×55 recto-verso couché mat 300 g pelliculage mat | D7: Impression numérique petit format | H7: 0.0125 | AK7: 0.045 | AQ7: 0.012 | BC7: 0.1 | BM7: 0.04 | BQ7: 0.27
A8: ART-0007 | B8: Carte de visite | C8: 85×55 recto-verso couché mat 300 g pelliculage brillant | D8: Impression numérique petit format | H8: 0.0125 | AL8: 0.045 | AQ8: 0.012 | BC8: 0.1 | BM8: 0.04 | BQ8: 0.27
A9: ART-0008 | B9: Carte de visite | C9: 85×55 recto-verso couché mat 300 g pelliculage mat + vernis sélectif | D9: Impression numérique petit format | H9: 0.0125 | AK9: 0.045 | AQ9: 0.012 | BA9: 0.03 | BC9: 0.1 | BM9: 0.04 | BQ9: 0.27 | BS9: 0.15
A10: ART-0009 | B10: Carte de visite | C10: 85×55 recto création 300 g | D10: Impression numérique petit format | M10: 0.0125 | AQ10: 0.006 | BC10: 0.05 | BM10: 0.04
A11: ART-0010 | B11: Carte de visite | C11: 85×55 recto création 300 g pelliculage mat | D11: Impression numérique petit format | M11: 0.0125 | AK11: 0.0225 | AQ11: 0.006 | BC11: 0.05 | BM11: 0.04 | BQ11: 0.14
A12: ART-0011 | B12: Carte de visite | C12: 85×55 recto création 300 g pelliculage brillant | D12: Impression numérique petit format | M12: 0.0125 | AL12: 0.0225 | AQ12: 0.006 | BC12: 0.05 | BM12: 0.04 | BQ12: 0.14
A13: ART-0012 | B13: Carte de visite | C13: 85×55 recto création 300 g pelliculage mat + vernis sélectif | D13: Impression numérique petit format | M13: 0.0125 | AK13: 0.0225 | AQ13: 0.006 | BA13: 0.03 | BC13: 0.05 | BM13: 0.04 | BQ13: 0.14 | BS13: 0.15
A14: ART-0013 | B14: Carte de visite | C14: 85×55 recto-verso création 300 g | D14: Impression numérique petit format | M14: 0.0125 | AQ14: 0.012 | BC14: 0.1 | BM14: 0.04
A15: ART-0014 | B15: Carte de visite | C15: 85×55 recto-verso création 300 g pelliculage mat | D15: Impression numérique petit format | M15: 0.0125 | AK15: 0.045 | AQ15: 0.012 | BC15: 0.1 | BM15: 0.04 | BQ15: 0.27
A16: ART-0015 | B16: Carte de visite | C16: 85×55 recto-verso création 300 g pelliculage brillant | D16: Impression numérique petit format | M16: 0.0125 | AL16: 0.045 | AQ16: 0.012 | BC16: 0.1 | BM16: 0.04 | BQ16: 0.27
A17: ART-0016 | B17: Carte de visite | C17: 85×55 recto-verso création 300 g pelliculage mat + vernis sélectif | D17: Impression numérique petit format | M17: 0.0125 | AK17: 0.045 | AQ17: 0.012 | BA17: 0.03 | BC17: 0.1 | BM17: 0.04 | BQ17: 0.27 | BS17: 0.15
A18: ART-0017 | B18: Flyer | C18: A6 recto couché brillant 130 g | D18: Impression numérique petit format | E18: 0.0328 | AQ18: 0.0158 | BC18: 0.13 | BM18: 0.06
A19: ART-0018 | B19: Flyer | C19: A6 recto-verso couché brillant 130 g | D19: Impression numérique petit format | E19: 0.0328 | AQ19: 0.0315 | BC19: 0.26 | BM19: 0.06
A20: ART-0019 | B20: Flyer | C20: A6 recto couché brillant 170 g | D20: Impression numérique petit format | F20: 0.0328 | AQ20: 0.0158 | BC20: 0.13 | BM20: 0.06
A21: ART-0020 | B21: Flyer | C21: A6 recto-verso couché brillant 170 g | D21: Impression numérique petit format | F21: 0.0328 | AQ21: 0.0315 | BC21: 0.26 | BM21: 0.06
A22: ART-0021 | B22: Flyer | C22: A6 recto couché mat 250 g | D22: Impression numérique petit format | G22: 0.0328 | AQ22: 0.0158 | BC22: 0.13 | BM22: 0.06
A23: ART-0022 | B23: Flyer | C23: A6 recto-verso couché mat 250 g | D23: Impression numérique petit format | G23: 0.0328 | AQ23: 0.0315 | BC23: 0.26 | BM23: 0.06
A24: ART-0023 | B24: Flyer | C24: A5 recto couché brillant 130 g | D24: Impression numérique petit format | E24: 0.0656 | AQ24: 0.0315 | BC24: 0.26 | BM24: 0.08
A25: ART-0024 | B25: Flyer | C25: A5 recto-verso couché brillant 130 g | D25: Impression numérique petit format | E25: 0.0656 | AQ25: 0.063 | BC25: 0.53 | BM25: 0.08
A26: ART-0025 | B26: Flyer | C26: A5 recto couché brillant 170 g | D26: Impression numérique petit format | F26: 0.0656 | AQ26: 0.0315 | BC26: 0.26 | BM26: 0.08
A27: ART-0026 | B27: Flyer | C27: A5 recto-verso couché brillant 170 g | D27: Impression numérique petit format | F27: 0.0656 | AQ27: 0.063 | BC27: 0.53 | BM27: 0.08
A28: ART-0027 | B28: Flyer | C28: A5 recto couché mat 250 g | D28: Impression numérique petit format | G28: 0.0656 | AQ28: 0.0315 | BC28: 0.26 | BM28: 0.08
A29: ART-0028 | B29: Flyer | C29: A5 recto-verso couché mat 250 g | D29: Impression numérique petit format | G29: 0.0656 | AQ29: 0.063 | BC29: 0.53 | BM29: 0.08
A30: ART-0029 | B30: Flyer | C30: A4 recto couché brillant 130 g | D30: Impression numérique petit format | E30: 0.1313 | AQ30: 0.063 | BC30: 0.53 | BM30: 0.14
A31: ART-0030 | B31: Flyer | C31: A4 recto-verso couché brillant 130 g | D31: Impression numérique petit format | E31: 0.1313 | AQ31: 0.126 | BC31: 1.05 | BM31: 0.14
A32: ART-0031 | B32: Flyer | C32: A4 recto couché brillant 170 g | D32: Impression numérique petit format | F32: 0.1313 | AQ32: 0.063 | BC32: 0.53 | BM32: 0.14
A33: ART-0032 | B33: Flyer | C33: A4 recto-verso couché brillant 170 g | D33: Impression numérique petit format | F33: 0.1313 | AQ33: 0.126 | BC33: 1.05 | BM33: 0.14
A34: ART-0033 | B34: Flyer | C34: A4 recto couché mat 250 g | D34: Impression numérique petit format | G34: 0.1313 | AQ34: 0.063 | BC34: 0.53 | BM34: 0.14
A35: ART-0034 | B35: Flyer | C35: A4 recto-verso couché mat 250 g | D35: Impression numérique petit format | G35: 0.1313 | AQ35: 0.126 | BC35: 1.05 | BM35: 0.14
A36: ART-0035 | B36: Flyer | C36: DL recto couché brillant 130 g | D36: Impression numérique petit format | E36: 0.0438 | AQ36: 0.021 | BC36: 0.18 | BM36: 0.07
A37: ART-0036 | B37: Flyer | C37: DL recto-verso couché brillant 130 g | D37: Impression numérique petit format | E37: 0.0438 | AQ37: 0.042 | BC37: 0.35 | BM37: 0.07
A38: ART-0037 | B38: Flyer | C38: DL recto couché brillant 170 g | D38: Impression numérique petit format | F38: 0.0438 | AQ38: 0.021 | BC38: 0.18 | BM38: 0.07
A39: ART-0038 | B39: Flyer | C39: DL recto-verso couché brillant 170 g | D39: Impression numérique petit format | F39: 0.0438 | AQ39: 0.042 | BC39: 0.35 | BM39: 0.07
A40: ART-0039 | B40: Flyer | C40: DL recto couché mat 250 g | D40: Impression numérique petit format | G40: 0.0438 | AQ40: 0.021 | BC40: 0.18 | BM40: 0.07
...

Sheet LISEZ-MOI
A1: BASE ARTICLE – Imprimerie numérique (Digiprint)
A2: Base de données de travail générée pour le cahier de spécifications – valeurs réalistes à valider par le Responsable Stock et la Production
A4: STRUCTURE
A5: BASE_ARTICLE | B5: Table principale au format du gabarit : ID, Désignation, Nature, Catégorie, IMPUT1–50 (quantité d'intrant par unité d'article), MACH1–20 (temps de passage machine par unité d'article). Cellule vide = intrant / machine non utilisé.
A6: ATTRIBUTS_ARTICLE | B6: Unité de l'article, procédé, format fini, site de production et indicateurs calculés (nb d'intrants, nb de machines, temps machine total).
A7: REF_INTRANTS | B7: Correspondance IMPUTn → libellé, famille, UoM achat → UoM consommation, facteur de conversion, source.
A8: REF_MACHINES | B8: Correspondance MACHn → machine, atelier, site, cadence de référence, source.
A9: HORS_NOMENCLATURE | B9: Consommables et pièces d'usure gérés en stock mais non affectés à un article (frais d'atelier / maintenance).
A10: SYNTHESE | B10: Contrôles : répartition des articles par catégorie et par site.
A12: CONVENTIONS
A13: Unités intrants | B13: Exprimées dans l'UoM de consommation de REF_INTRANTS (feuille A0, ml, pièce, g, kg). Ex. : 0,0125 feuille A0 = une carte de visite.
A14: Unités machines | B14: Secondes par unité d'article. L'unité d'article est donnée dans ATTRIBUTS_ARTICLE : pièce, m², ml, paire, kit, ou lot de 1 000 (offset / Presstek, calage inclus).
A15: Nomenclature | B15: Désignation générique et courte ; la Nature porte le format, le support, l'impression et la finition (règle « sac » / « cabas »).
A17: HYPOTHÈSES DE CALCUL
A18: Papier numérique | B18: 1 feuille A0 = 4 feuilles SRA3 (320×450) ; gâche 5 %. Poses/SRA3 : carte 21, A6 8, A5 4, A4 2, A3 1, DL 6.
A19: Encre Indigo | B19: 0,12 ml / face SRA3 quadri (N/B texte : 30–40 %).
A20: HP Indigo | B20: 1 s / face SRA3.
A21: Offset | B21: Feuille presse ≈ A1 (½ A0) ; gâche 8 % ; poses A1 : A6 24, A5 12, A4 6, DL 14, A3 3, A2 1 ; 3 g d'encre / face quadri ; 0,15 ml de mouillage / face ; 4 plaques / face quadri ; 8 000 f/h ; calage 15 min / face. Brochures : cahiers de 16 pages.
A22: Presstek DI | B22: Feuille SRA3 ; gâche 6 % ; 0,8 g d'encre / face quadri ; waterless (pas de mouillage) ; calage 6 min / face ; plaques DI hors nomenclature.
A23: Grand format | B23: Encre 10 ml/m² ; 15 m²/h bâche, 20 m²/h papier affiche, 12 m²/h tissu ; imbrication max. 3 poses dans la laize ; marge 0,10 ml ; œillet tous les 50 cm ; ourlet 20 s/m.
A24: DTF | B24: Film : surface / 0,60 × 1,2 ; encre 18 ml/m² (+25 % sur textile couleur) ; poudre 90 g/m² ; 8 m²/h ; presse 25 s / transfert.
A25: Sérigraphie | B25: Plastisol 6 g / couleur / A4 (+1 couche de fond sur textile couleur) ; écrans et insolation amortis sur une série de référence de 100 pièces (500 pour objets).
A26: Sublimation | B26: Papier : surface / 1,10 × 1,15 + 0,02 ml ; encre 12 ml/m² ; presse plate 60 s / face ; presse à mug 210 s (mug), 240 s (gourde).
A27: Finition | B27: Pelliculage : 0,45 ml de film / face SRA3, 10 ml/min ; Jet Varnish : 0,6 ml et 3 s / SRA3 ; plotter : 60 s / SRA3.
A29: À VALIDER | B29: Les colonnes « Source » marquées « à confirmer » sont des propositions à vérifier auprès du Responsable Stock (grammages, laizes, conditionnements, équipements DTF / sublimation / sérigraphie, format de la presse offset).

Sheet ATTRIBUTS_ARTICLE
A1: ID_ARTICLES | B1: DESIGNATION | C1: UNITE_ARTICLE | D1: PROCEDE_PRINCIPAL | E1: FORMAT_FINI | F1: SITE_PRODUCTION | G1: NB_INTRANTS | H1: NB_MACHINES | I1: TEMPS_MACHINE_TOTAL (s) | J1: TEMPS_MACHINE_TOTAL (min)
A2: =BASE_ARTICLE!A2 -> ART-0001 | B2: =BASE_ARTICLE!B2 -> Carte de visite | C2: pièce | D2: Numérique HP Indigo | E2: 85×55 mm | F2: Siège | G2: =COUNT(BASE_ARTICLE!E2:BB2) -> 2 | H2: =COUNT(BASE_ARTICLE!BC2:BV2) -> 2 | I2: =SUM(BASE_ARTICLE!BC2:BV2) -> 0.09 | J2: =I2/60 -> 0.0015
A3: =BASE_ARTICLE!A3 -> ART-0002 | B3: =BASE_ARTICLE!B3 -> Carte de visite | C3: pièce | D3: Numérique HP Indigo | E3: 85×55 mm | F3: Siège | G3: =COUNT(BASE_ARTICLE!E3:BB3) -> 3 | H3: =COUNT(BASE_ARTICLE!BC3:BV3) -> 3 | I3: =SUM(BASE_ARTICLE!BC3:BV3) -> 0.23 | J3: =I3/60 -> 0.0038333333
A4: =BASE_ARTICLE!A4 -> ART-0003 | B4: =BASE_ARTICLE!B4 -> Carte de visite | C4: pièce | D4: Numérique HP Indigo | E4: 85×55 mm | F4: Siège | G4: =COUNT(BASE_ARTICLE!E4:BB4) -> 3 | H4: =COUNT(BASE_ARTICLE!BC4:BV4) -> 3 | I4: =SUM(BASE_ARTICLE!BC4:BV4) -> 0.23 | J4: =I4/60 -> 0.0038333333
A5: =BASE_ARTICLE!A5 -> ART-0004 | B5: =BASE_ARTICLE!B5 -> Carte de visite | C5: pièce | D5: Numérique HP Indigo | E5: 85×55 mm | F5: Siège | G5: =COUNT(BASE_ARTICLE!E5:BB5) -> 4 | H5: =COUNT(BASE_ARTICLE!BC5:BV5) -> 4 | I5: =SUM(BASE_ARTICLE!BC5:BV5) -> 0.38 | J5: =I5/60 -> 0.0063333333
A6: =BASE_ARTICLE!A6 -> ART-0005 | B6: =BASE_ARTICLE!B6 -> Carte de visite | C6: pièce | D6: Numérique HP Indigo | E6: 85×55 mm | F6: Siège | G6: =COUNT(BASE_ARTICLE!E6:BB6) -> 2 | H6: =COUNT(BASE_ARTICLE!BC6:BV6) -> 2 | I6: =SUM(BASE_ARTICLE!BC6:BV6) -> 0.14 | J6: =I6/60 -> 0.0023333333
A7: =BASE_ARTICLE!A7 -> ART-0006 | B7: =BASE_ARTICLE!B7 -> Carte de visite | C7: pièce | D7: Numérique HP Indigo | E7: 85×55 mm | F7: Siège | G7: =COUNT(BASE_ARTICLE!E7:BB7) -> 3 | H7: =COUNT(BASE_ARTICLE!BC7:BV7) -> 3 | I7: =SUM(BASE_ARTICLE!BC7:BV7) -> 0.41 | J7: =I7/60 -> 0.0068333333
A8: =BASE_ARTICLE!A8 -> ART-0007 | B8: =BASE_ARTICLE!B8 -> Carte de visite | C8: pièce | D8: Numérique HP Indigo | E8: 85×55 mm | F8: Siège | G8: =COUNT(BASE_ARTICLE!E8:BB8) -> 3 | H8: =COUNT(BASE_ARTICLE!BC8:BV8) -> 3 | I8: =SUM(BASE_ARTICLE!BC8:BV8) -> 0.41 | J8: =I8/60 -> 0.0068333333
A9: =BASE_ARTICLE!A9 -> ART-0008 | B9: =BASE_ARTICLE!B9 -> Carte de visite | C9: pièce | D9: Numérique HP Indigo | E9: 85×55 mm | F9: Siège | G9: =COUNT(BASE_ARTICLE!E9:BB9) -> 4 | H9: =COUNT(BASE_ARTICLE!BC9:BV9) -> 4 | I9: =SUM(BASE_ARTICLE!BC9:BV9) -> 0.56 | J9: =I9/60 -> 0.0093333333
A10: =BASE_ARTICLE!A10 -> ART-0009 | B10: =BASE_ARTICLE!B10 -> Carte de visite | C10: pièce | D10: Numérique HP Indigo | E10: 85×55 mm | F10: Siège | G10: =COUNT(BASE_ARTICLE!E10:BB10) -> 2 | H10: =COUNT(BASE_ARTICLE!BC10:BV10) -> 2 | I10: =SUM(BASE_ARTICLE!BC10:BV10) -> 0.09 | J10: =I10/60 -> 0.0015
A11: =BASE_ARTICLE!A11 -> ART-0010 | B11: =BASE_ARTICLE!B11 -> Carte de visite | C11: pièce | D11: Numérique HP Indigo | E11: 85×55 mm | F11: Siège | G11: =COUNT(BASE_ARTICLE!E11:BB11) -> 3 | H11: =COUNT(BASE_ARTICLE!BC11:BV11) -> 3 | I11: =SUM(BASE_ARTICLE!BC11:BV11) -> 0.23 | J11: =I11/60 -> 0.0038333333
A12: =BASE_ARTICLE!A12 -> ART-0011 | B12: =BASE_ARTICLE!B12 -> Carte de visite | C12: pièce | D12: Numérique HP Indigo | E12: 85×55 mm | F12: Siège | G12: =COUNT(BASE_ARTICLE!E12:BB12) -> 3 | H12: =COUNT(BASE_ARTICLE!BC12:BV12) -> 3 | I12: =SUM(BASE_ARTICLE!BC12:BV12) -> 0.23 | J12: =I12/60 -> 0.0038333333
A13: =BASE_ARTICLE!A13 -> ART-0012 | B13: =BASE_ARTICLE!B13 -> Carte de visite | C13: pièce | D13: Numérique HP Indigo | E13: 85×55 mm | F13: Siège | G13: =COUNT(BASE_ARTICLE!E13:BB13) -> 4 | H13: =COUNT(BASE_ARTICLE!BC13:BV13) -> 4 | I13: =SUM(BASE_ARTICLE!BC13:BV13) -> 0.38 | J13: =I13/60 -> 0.0063333333
... A274: =BASE_ARTICLE!A274 -> ART-0273 | B274: =BASE_ARTICLE!B274 -> Kit | C274: kit | D274: Assemblage | E274: kit | F274: Siège | G274: =COUNT(BASE_ARTICLE!E274:BB274) -> 8 | H274: =COUNT(BASE_ARTICLE!BC274:BV274) -> 5 | I274: =SUM(BASE_ARTICLE!BC274:BV274) -> 395.12 | J274: =I274/60 -> 6.5853333

Sheet REF_INTRANTS
A1: CODE | B1: LIBELLE | C1: FAMILLE | D1: CATEGORIE_STOCK | E1: UOM_ACHAT | F1: CONDITIONNEMENT | G1: UOM_CONSO | H1: FACTEUR_CONVERSION | I1: SOURCE | J1: NB_ARTICLES_UTILISATEURS
A2: IMPUT1 | B2: Papier couché brillant 130 g | C2: Matière première | D2: Papier | E2: Paquet | F2: 125 feuilles A0 | G2: feuille A0 | H2: 125 | I2: CDC (A0) ; grammage à confirmer | J2: =COUNT(BASE_ARTICLE!E2:E274) -> 52
A3: IMPUT2 | B3: Papier couché brillant 170 g | C3: Matière première | D3: Papier | E3: Paquet | F3: 100 feuilles A0 | G3: feuille A0 | H3: 100 | I3: CDC (paquet A0 170 g) | J3: =COUNT(BASE_ARTICLE!F2:F274) -> 24
A4: IMPUT3 | B4: Papier couché mat 250 g | C4: Matière première | D4: Papier | E4: Paquet | F4: 100 feuilles A0 | G4: feuille A0 | H4: 100 | I4: CDC (A0) ; grammage à confirmer | J4: =COUNT(BASE_ARTICLE!G2:G274) -> 40
A5: IMPUT4 | B5: Papier couché mat 300 g | C5: Matière première | D5: Papier | E5: Paquet | F5: 100 feuilles A0 | G5: feuille A0 | H5: 100 | I5: CDC (A0) ; grammage à confirmer | J5: =COUNT(BASE_ARTICLE!H2:H274) -> 35
A6: IMPUT5 | B6: Papier offset 80 g | C6: Matière première | D6: Papier | E6: Paquet | F6: 250 feuilles A0 | G6: feuille A0 | H6: 250 | I6: CDC ; à confirmer | J6: =COUNT(BASE_ARTICLE!I2:I274) -> 32
A7: IMPUT6 | B7: Papier offset 120 g | C7: Matière première | D7: Papier | E7: Paquet | F7: 125 feuilles A0 | G7: feuille A0 | H7: 125 | I7: CDC ; à confirmer | J7: =COUNT(BASE_ARTICLE!J2:J274) -> 1
A8: IMPUT7 | B8: Carton couché 350 g | C8: Matière première | D8: Papier | E8: Paquet | F8: 100 feuilles A0 | G8: feuille A0 | H8: 100 | I8: CDC (carton) | J8: =COUNT(BASE_ARTICLE!K2:K274) -> 31
A9: IMPUT8 | B9: Papier adhésif couché brillant | C9: Matière première | D9: Papier | E9: Paquet | F9: 100 feuilles A0 | G9: feuille A0 | H9: 100 | I9: À confirmer | J9: =COUNT(BASE_ARTICLE!L2:L274) -> 11
A10: IMPUT9 | B10: Papier création texturé 300 g | C10: Matière première | D10: Papier | E10: Paquet | F10: 100 feuilles A0 | G10: feuille A0 | H10: 100 | I10: CDC (couverture) ; à confirmer | J10: =COUNT(BASE_ARTICLE!M2:M274) -> 14
A11: IMPUT10 | B11: Bâche frontlit 440 g – laize 3,20 m | C11: Matière première | D11: Grand format | E11: Rouleau | F11: 50 ml | G11: ml | H11: 50 | I11: CDC | J11: =COUNT(BASE_ARTICLE!N2:N274) -> 19
A12: IMPUT11 | B12: Vinyle adhésif blanc – laize 1,37 m | C12: Matière première | D12: Grand format | E12: Rouleau | F12: 50 ml | G12: ml | H12: 50 | I12: CDC | J12: =COUNT(BASE_ARTICLE!O2:O274) -> 4
A13: IMPUT12 | B13: Vinyle microperforé (vitrophanie) – laize 1,37 m | C13: Matière première | D13: Grand format | E13: Rouleau | F13: 50 ml | G13: ml | H13: 50 | I13: À confirmer | J13: =COUNT(BASE_ARTICLE!P2:P274) -> 1
A14: IMPUT13 | B14: Papier affiche 150 g – laize 1,07 m | C14: Matière première | D14: Grand format | E14: Rouleau | F14: 50 ml | G14: ml | H14: 50 | I14: CDC | J14: =COUNT(BASE_ARTICLE!Q2:Q274) -> 5
A15: IMPUT14 | B15: Toile PET roll-up / kakémono – laize 0,91 m | C15: Matière première | D15: Grand format | E15: Rouleau | F15: 30 ml | G15: ml | H15: 30 | I15: CDC | J15: =COUNT(BASE_ARTICLE!R2:R274) -> 7
A16: IMPUT15 | B16: Tissu polyester (banderole, drapeau) – laize 1,60 m | C16: Matière première | D16: Grand format | E16: Rouleau | F16: 50 ml | G16: ml | H16: 50 | I16: CDC | J16: =COUNT(BASE_ARTICLE!S2:S274) -> 4
A17: IMPUT16 | B17: T-shirt coton blanc vierge | C17: Matière première | D17: Textile | E17: Carton | F17: 50 pièces | G17: pièce | H17: 50 | I17: CDC | J17: =COUNT(BASE_ARTICLE!T2:T274) -> 9
A18: IMPUT17 | B18: T-shirt coton couleur vierge | C18: Matière première | D18: Textile | E18: Carton | F18: 50 pièces | G18: pièce | H18: 50 | I18: CDC | J18: =COUNT(BASE_ARTICLE!U2:U274) -> 10
A19: IMPUT18 | B19: Polo piqué vierge | C19: Matière première | D19: Textile | E19: Carton | F19: 25 pièces | G19: pièce | H19: 25 | I19: CDC | J19: =COUNT(BASE_ARTICLE!V2:V274) -> 5
A20: IMPUT19 | B20: Casquette vierge | C20: Matière première | D20: Textile | E20: Carton | F20: 100 pièces | G20: pièce | H20: 100 | I20: CDC | J20: =COUNT(BASE_ARTICLE!W2:W274) -> 4
A21: IMPUT20 | B21: T-shirt polyester blanc sublimable | C21: Matière première | D21: Textile | E21: Carton | F21: 50 pièces | G21: pièce | H21: 50 | I21: À confirmer | J21: =COUNT(BASE_ARTICLE!X2:X274) -> 4
A22: IMPUT21 | B22: Support cuir synthétique prédécoupé | C22: Matière première | D22: Cuir et supports spéciaux | E22: Lot | F22: 50 pièces | G22: pièce | H22: 50 | I22: Web | J22: =COUNT(BASE_ARTICLE!Y2:Y274) -> 5
A23: IMPUT22 | B23: Stylo plastique vierge | C23: Matière première | D23: Négoce / gadgets | E23: Carton | F23: 500 pièces | G23: pièce | H23: 500 | I23: CDC | J23: =COUNT(BASE_ARTICLE!Z2:Z274) -> 6
A24: IMPUT23 | B24: Mug céramique blanc sublimable 11 oz | C24: Matière première | D24: Négoce / gadgets | E24: Carton | F24: 36 pièces | G24: pièce | H24: 36 | I24: CDC | J24: =COUNT(BASE_ARTICLE!AA2:AA274) -> 5
A25: IMPUT24 | B25: Gourde aluminium sublimable 500 ml | C25: Matière première | D25: Négoce / gadgets | E25: Carton | F25: 50 pièces | G25: pièce | H25: 50 | I25: CDC | J25: =COUNT(BASE_ARTICLE!AB2:AB274) -> 5
A26: IMPUT25 | B26: Bracelet silicone vierge | C26: Matière première | D26: Négoce / gadgets | E26: Lot | F26: 100 pièces | G26: pièce | H26: 100 | I26: CDC | J26: =COUNT(BASE_ARTICLE!AC2:AC274) -> 3
A27: IMPUT26 | B27: Sac cabas papier (tote bag) vierge | C27: Matière première | D27: Négoce / gadgets | E27: Lot | F27: 100 pièces | G27: pièce | H27: 100 | I27: CDC | J27: =COUNT(BASE_ARTICLE!AD2:AD274) -> 7
A28: IMPUT27 | B28: Enveloppe blanche DL 110×220 | C28: Matière première | D28: Emballage / packaging | E28: Boîte | F28: 500 pièces | G28: pièce | H28: 500 | I28: Web | J28: =COUNT(BASE_ARTICLE!AE2:AE274) -> 2
A29: IMPUT28 | B29: Sachet kraft vierge | C29: Matière première | D29: Emballage / packaging | E29: Lot | F29: 100 pièces | G29: pièce | H29: 100 | I29: Web | J29: =COUNT(BASE_ARTICLE!AF2:AF274) -> 2
A30: IMPUT29 | B30: Spirale métallique | C30: Matière première | D30: Reliure | E30: Boîte | F30: 100 pièces | G30: pièce | H30: 100 | I30: Web ; à confirmer | J30: =COUNT(BASE_ARTICLE!AG2:AG274) -> 14
A31: IMPUT30 | B31: Colle hotmelt dos carré collé | C31: Matière première | D31: Reliure | E31: Sac | F31: 5 kg | G31: kg | H31: 5 | I31: Web ; à confirmer | J31: =COUNT(BASE_ARTICLE!AH2:AH274) -> 24
A32: IMPUT31 | B32: Agrafes piqûre à cheval | C32: Matière première | D32: Reliure | E32: Boîte | F32: 5 000 pièces | G32: pièce | H32: 5000 | I32: Web ; à confirmer | J32: =COUNT(BASE_ARTICLE!AI2:AI274) -> 19
A33: IMPUT32 | B33: Couverture transparente (rhodoïd) A4 | C33: Matière première | D33: Reliure | E33: Boîte | F33: 100 pièces | G33: pièce | H33: 100 | I33: Web ; à confirmer | J33: =COUNT(BASE_ARTICLE!AJ2:AJ274) -> 7
A34: IMPUT33 | B34: Film de pelliculage mat – laize 0,33 m | C34: Matière première | D34: Finition (matière) | E34: Rouleau | F34: 200 ml | G34: ml | H34: 200 | I34: CDC ; à confirmer | J34: =COUNT(BASE_ARTICLE!AK2:AK274) -> 64
A35: IMPUT34 | B35: Film de pelliculage brillant – laize 0,33 m | C35: Matière première | D35: Finition (matière) | E35: Rouleau | F35: 200 ml | G35: ml | H35: 200 | I35: CDC ; à confirmer | J35: =COUNT(BASE_ARTICLE!AL2:AL274) -> 10
A36: IMPUT35 | B36: Œillets métalliques | C36: Matière première | D36: Finition (matière) | E36: Boîte | F36: 1 000 pièces | G36: pièce | H36: 1000 | I36: CDC ; à confirmer | J36: =COUNT(BASE_ARTICLE!AM2:AM274) -> 20
A37: IMPUT36 | B37: Cassette roll-up (structure + sac) | C37: Matière première | D37: Finition (matière) | E37: Carton | F37: 10 pièces | G37: pièce | H37: 10 | I37: CDC ; à confirmer | J37: =COUNT(BASE_ARTICLE!AN2:AN274) -> 4
A38: IMPUT37 | B38: Baguettes aluminium kakémono (paire) | C38: Matière première | D38: Finition (matière) | E38: Lot | F38: 20 paires | G38: paire | H38: 20 | I38: CDC ; à confirmer | J38: =COUNT(BASE_ARTICLE!AO2:AO274) -> 3
A39: IMPUT38 | B39: Plaque offset (prestataire Aziz) | C39: Matière première | D39: Plaques offset | E39: Pièce | F39: 1 pièce | G39: pièce | H39: 1 | I39: CDC | J39: =COUNT(BASE_ARTICLE!AP2:AP274) -> 28
A40: IMPUT39 | B40: Encre HP Indigo ElectroInk (CMJN) | C40: Consommable | D40: Encres numérique | E40: Bidon | F40: 1 000 ml | G40: ml | H40: 1000 | I40: Web ; références à confirmer | J40: =COUNT(BASE_ARTICLE!AQ2:AQ274) -> 150
...

Sheet REF_MACHINES
A1: yt | B1: MACHINE | C1: ATELIER | D1: SITE | E1: UNITE_TEMPS | F1: CADENCE_REFERENCE | G1: SOURCE | H1: NB_ARTICLES_UTILISATEURS
A2: MACH1 | B2: HP Indigo – presse numérique feuille | C2: Impression numérique | D2: Siège | E2: seconde | F2: ≈ 1 s / feuille SRA3 / face (quadri) | G2: Web | H2: =COUNT(BASE_ARTICLE!BC2:BC274) -> 150
A3: MACH2 | B3: Presstek DI – offset numérique waterless | C3: Impression numérique | D3: Siège | E3: seconde | F3: ≈ 10 000 feuilles SRA3/h ; calage 6 min/face | G3: Web | H3: =COUNT(BASE_ARTICLE!BD2:BD274) -> 9
A4: MACH3 | B4: Imprimante DTF | C4: DTF | D4: Siège | E4: seconde | F4: ≈ 8 m²/h | G4: CDC (activité) ; équipement à confirmer | H4: =COUNT(BASE_ARTICLE!BE2:BE274) -> 25
A5: MACH4 | B5: Poudreuse / four DTF | C5: DTF | D5: Siège | E5: seconde | F5: ≈ 12 m²/h | G5: À confirmer | H5: =COUNT(BASE_ARTICLE!BF2:BF274) -> 25
A6: MACH5 | B6: Presse à chaud plate | C6: DTF / Sublimation | D6: Siège | E6: seconde | F6: 25–60 s / transfert (manutention incluse) | G6: À confirmer | H6: =COUNT(BASE_ARTICLE!BG2:BG274) -> 29
A7: MACH6 | B7: Imprimante sublimation | C7: Sublimation | D7: Siège | E7: seconde | F7: ≈ 10 m²/h | G7: À confirmer | H7: =COUNT(BASE_ARTICLE!BH2:BH274) -> 13
A8: MACH7 | B8: Presse à mug / objets cylindriques | C8: Sublimation | D8: Siège | E8: seconde | F8: 180–240 s / pièce | G8: À confirmer | H8: =COUNT(BASE_ARTICLE!BI2:BI274) -> 9
A9: MACH8 | B9: Carrousel / table de sérigraphie | C9: Sérigraphie | D9: Siège | E9: seconde | F9: 20 s + 5 s / couleur / pièce | G9: À confirmer | H9: =COUNT(BASE_ARTICLE!BJ2:BJ274) -> 20
A10: MACH9 | B10: Insoleuse | C10: Sérigraphie | D10: Siège | E10: seconde | F10: 150 s / écran | G10: À confirmer | H10: =COUNT(BASE_ARTICLE!BK2:BK274) -> 20
A11: MACH10 | B11: Tunnel de séchage | C11: Sérigraphie | D11: Siège | E11: seconde | F11: ≈ 120 pièces/h | G11: À confirmer | H11: =COUNT(BASE_ARTICLE!BL2:BL274) -> 14
A12: MACH11 | B12: Massicot | C12: Finition | D12: Siège | E12: seconde | F12: 0,2 s / feuille + 0,03 s / pose | G12: CDC | H12: =COUNT(BASE_ARTICLE!BM2:BM274) -> 166
A13: MACH12 | B13: Plieuse / piqueuse | C13: Finition | D13: Siège | E13: seconde | F13: ≈ 12 000 plis/h ; piqûre 3 s / ex. | G13: CDC (piqueuse à confirmer) | H13: =COUNT(BASE_ARTICLE!BN2:BN274) -> 51
A14: MACH13 | B14: Relieuse dos carré collé | C14: Finition | D14: Siège | E14: seconde | F14: ≈ 180 ex./h | G14: CDC | H14: =COUNT(BASE_ARTICLE!BO2:BO274) -> 24
A15: MACH14 | B15: Relieuse spirale (perforelieuse) | C15: Finition | D15: Siège | E15: seconde | F15: 20 s + 0,5 s / feuille | G15: CDC | H15: =COUNT(BASE_ARTICLE!BP2:BP274) -> 14
A16: MACH15 | B16: Pelliculeuse | C16: Finition | D16: Siège | E16: seconde | F16: 10 ml/min | G16: CDC | H16: =COUNT(BASE_ARTICLE!BQ2:BQ274) -> 74
A17: MACH16 | B17: Plotter de découpe | C17: Finition | D17: Siège | E17: seconde | F17: 60 s / feuille SRA3 ; 300 s / m² vinyle | G17: CDC | H17: =COUNT(BASE_ARTICLE!BR2:BR274) -> 27
A18: MACH17 | B18: Jet Varnish – vernis sélectif | C18: Finition | D18: Siège | E18: seconde | F18: ≈ 3 s / feuille SRA3 | G18: Web | H18: =COUNT(BASE_ARTICLE!BS2:BS274) -> 10
A19: MACH18 | B19: Imprimante grand format | C19: Grand format | D19: Angré | E19: seconde | F19: ≈ 15 m²/h (bâche) | G19: CDC | H19: =COUNT(BASE_ARTICLE!BT2:BT274) -> 40
A20: MACH19 | B20: Presse offset | C20: Offset | D20: Angré | E20: seconde | F20: 8 000 feuilles/h ; calage 15 min/face | G20: CDC (format : point ouvert) | H20: =COUNT(BASE_ARTICLE!BU2:BU274) -> 28
A21: MACH20 | B21: Poste finition grand format (œilletonneuse / soudeuse) | C21: Grand format | D21: Angré | E21: seconde | F21: 20 s / m d'ourlet ; 8 s / œillet | G21: À confirmer | H21: =COUNT(BASE_ARTICLE!BV2:BV274) -> 40

Sheet HORS_NOMENCLATURE
A1: DESIGNATION | B1: CATEGORIE | C1: UOM_GESTION | D1: MACHINE / ATELIER | E1: MODE_D'AFFECTATION | F1: SOURCE
A2: Encres offset tons directs (Pantone) | B2: Encres offset | C2: Boîte / kg | D2: Presse offset | E2: Consommation au travail (tons directs) | F2: CDC
A3: Cleaner plaques / blanchets | B3: Consommables offset | C3: Bidon | D3: Presse offset | E3: Frais d'atelier | F3: CDC
A4: Poudre antimaculante | B4: Consommables offset | C4: Boîte / kg | D4: Presse offset | E4: Frais d'atelier | F4: CDC
A5: Isopropanol (IPA) | B5: Consommables offset | C5: Fût / bidon | D5: Presse offset | E5: Frais d'atelier | F5: CDC
A6: Plaques Presstek DI (bobine) | B6: Consommables Presstek | C6: Bobine | D6: Presstek DI | E6: Consommation au calage | F6: À confirmer
A7: Diluant sérigraphie | B7: Sérigraphie | C7: Bidon | D7: Carrousel | E7: Frais d'atelier | F7: À confirmer
A8: Décapant / dégraissant écran | B8: Sérigraphie | C8: Bidon | D8: Insoleuse | E8: Frais d'atelier | F8: À confirmer
A9: Écrans / cadres sérigraphie | B9: Sérigraphie | C9: Pièce | D9: Carrousel | E9: Immobilisation / usure | F9: À confirmer
A10: Raclettes | B10: Sérigraphie | C10: Pièce | D10: Carrousel | E10: Pièce d'usure | F10: À confirmer
A11: Alcool de nettoyage | B11: Nettoyage | C11: Bidon | D11: Tous ateliers | E11: Frais d'atelier | F11: CDC
A12: Chiffons d'essuyage | B12: Nettoyage | C12: Lot | D12: Tous ateliers | E12: Frais d'atelier | F12: CDC
... A21: Téflon / feuille de protection presse à chaud | B21: Pièces d'usure | C21: Pièce | D21: Presses à chaud | E21: Maintenance | F21: À confirmer

Sheet SYNTHESE
A1: Synthèse de la base article
A4: CATEGORIE | B4: NB_ARTICLES | C4: % DU TOTAL
A5: Impression numérique petit format | B5: =COUNTIF(BASE_ARTICLE!$D$2:$D$274,A5) -> 76 | C5: =B5/$B$13 -> 0.27838828
A6: Édition et reliure | B6: =COUNTIF(BASE_ARTICLE!$D$2:$D$274,A6) -> 47 | C6: =B6/$B$13 -> 0.17216117
A7: Impression offset et Presstek | B7: =COUNTIF(BASE_ARTICLE!$D$2:$D$274,A7) -> 37 | C7: =B7/$B$13 -> 0.13553114
A8: Grand format et signalétique | B8: =COUNTIF(BASE_ARTICLE!$D$2:$D$274,A8) -> 39 | C8: =B8/$B$13 -> 0.14285714
A9: Textile personnalisé | B9: =COUNTIF(BASE_ARTICLE!$D$2:$D$274,A9) -> 27 | C9: =B9/$B$13 -> 0.098901099
A10: Objets publicitaires | B10: =COUNTIF(BASE_ARTICLE!$D$2:$D$274,A10) -> 17 | C10: =B10/$B$13 -> 0.062271062
A11: Packaging et étiquettes | B11: =COUNTIF(BASE_ARTICLE!$D$2:$D$274,A11) -> 22 | C11: =B11/$B$13 -> 0.080586081
A12: Coffrets et kits | B12: =COUNTIF(BASE_ARTICLE!$D$2:$D$274,A12) -> 8 | C12: =B12/$B$13 -> 0.029304029
A13: TOTAL | B13: =SUM(B5:B12) -> 273 | C13: =SUM(C5:C12) -> 1
A16: SITE_PRODUCTION | B16: NB_ARTICLES
A17: Siège | B17: =COUNTIF(ATTRIBUTS_ARTICLE!$F$2:$F$274,A17) -> 204
A18: Angré | B18: =COUNTIF(ATTRIBUTS_ARTICLE!$F$2:$F$274,A18) -> 37
A19: Angré + Siège | B19: =COUNTIF(ATTRIBUTS_ARTICLE!$F$2:$F$274,A19) -> 31
A20: Négoce (sans machine) | B20: =COUNTIF(ATTRIBUTS_ARTICLE!$F$2:$F$274,A20) -> 1
A21: TOTAL | B21: =SUM(B17:B20) -> 273
A23: Contrôle : total catégories = total sites | B23: =IF(B13=B21,"OK","ÉCART") -> OK
